<?xml version="1.0" ?>
<!-- =================================================================================== -->
<!-- |    This document was autogenerated by xacro from urdf/bvc.xacro                 | -->
<!-- |    EDITING THIS FILE BY HAND IS NOT RECOMMENDED                                 | -->
<!-- =================================================================================== -->
<robot name="mintaur" xmlns:xacro="http://www.ros.org/wiki/xacro">
  <material name="black">
    <color rgba="0.0 0.0 0.0 1.0"/>
  </material>
  <material name="blue">
    <color rgba="0.0 0.0 0.8 1.0"/>
  </material>
  <material name="green">
    <color rgba="0.0 0.8 0.0 1.0"/>
  </material>
  <material name="grey">
    <color rgba="0.2 0.2 0.2 1.0"/>
  </material>
  <material name="orange">
    <color rgba="1.0 0.423529411765 0.0392156862745 1.0"/>
  </material>
  <material name="brown">
    <color rgba="0.870588235294 0.811764705882 0.764705882353 1.0"/>
  </material>
  <material name="red">
    <color rgba="0.8 0.0 0.0 1.0"/>
  </material>
  <material name="white">
    <color rgba="1.0 1.0 1.0 1.0"/>
  </material>
  <material name="acrylic">
    <color rgba="1.0 1.0 1.0 0.4"/>
  </material>
  <!-- X axis direction is forward, Y axis direction is left -->
  <!-- ______________IMU parameters__________________________ -->
  <!-- <xacro:property name="imuL" value="0.05" />
    <xacro:property name="imuW" value="0.05" />
    <xacro:property name="imuH" value="0.05" />

    <xacro:property name="imuMass" value="10"/>
    <xacro:property name="imuIxx" value="0.4"/>
    <xacro:property name="imuIxy" value="0.4"/>
    <xacro:property name="imuIyy" value="0.4"/>
    <xacro:property name="imuIxz" value="0.4"/>
    <xacro:property name="imuIyz" value="0.4"/>
    <xacro:property name="imuIzz" value="0.4"/> -->
  <!-- <xacro:macro name="imu_inertial">
		<inertial>
            <mass value="${imuMass}"/>
            <inertia ixx="${imuIxx}" ixy="${imuIxy}" ixz="${imuIxz}" iyy="${imuIyy}" iyz="${imuIyz}" izz="${imuIzz}"/>
		</inertial>
	</xacro:macro> -->
  <!-- <xacro:macro name="imu_joint">
        <joint name="imu_joint" type="fixed">
            <axis xyz="0 1 0"/>
            <parent link="base_link"/>
            <child link="imu_link"/>
            <origin xyz="0 0 0" />
        </joint>
	</xacro:macro> -->
  <!-- <xacro:macro name="imu_geometry">
       <geometry>
            <box size = "${imuL} ${imuW} ${imuH} "/>
        </geometry>
	</xacro:macro> -->
  <!-- <xacro:macro name="imu">
    <link name="imu_link">
        <visual>
            <xacro:imu_geometry />
            <material name="orange"/>
        </visual>
        <collision>
            <xacro:imu_geometry />
        </collision>
        <xacro:imu_inertial />
    </link>

    <xacro:imu_joint />
</xacro:macro> -->
  <link name="base_link">
    <visual>
      <geometry>
        <mesh filename="/home/eichmeierbr/mrob/src/avc_urdf/meshes/chassis2.DAE" scale="0.001 0.001 0.001"/>
      </geometry>
      <origin rpy="1.57 0 0" xyz="-0.125 -0.07 -0.085"/>
    </visual>
    <collision>
      <geometry>
        <box size="0.51 0.2 0.15 "/>
      </geometry>
    </collision>
    <inertial>
      <mass value="1"/>
      <inertia ixx="0.4" ixy="0.4" ixz="0.0" iyy="0.4" iyz="0.0" izz="0.0"/>
    </inertial>
  </link>
  <link name="right_front_wheel">
    <visual>
      <geometry>
        <mesh filename="/home/eichmeierbr/mrob/src/avc_urdf/meshes/wheels.DAE" scale="0.001 0.001 0.001"/>
      </geometry>
      <origin rpy="1.57 0 0" xyz="0 0.022 0"/>
    </visual>
    <collision>
      <geometry>
        <cylinder length="0.043" radius="0.05"/>
      </geometry>
      <origin rpy="1.57075 0 0" xyz="0 0 0"/>
    </collision>
    <inertial>
      <mass value="1"/>
      <inertia ixx="0.4" ixy="0.0" ixz="0.0" iyy="0.4" iyz="0.0" izz="0.4"/>
    </inertial>
  </link>
  <link name="right_front_axle">
    <inertial>
      <mass value="0.001"/>
      <inertia ixx="0.0" ixy="0.0" ixz="0.0" iyy="0.0" iyz="0.0" izz="0.0"/>
    </inertial>
  </link>
  <joint name="base_to_right_front_axle" type="revolute">
    <axis xyz="0 0 1"/>
    <limit effort="0.001" lower="-0.785" upper="0.785" velocity="0.5"/>
    <parent link="base_link"/>
    <child link="right_front_axle"/>
    <origin xyz="0.1535 -0.1215 -0.075"/>
  </joint>
  <joint name="right_front_wheel_joint" type="continuous">
    <axis xyz="0 1 0"/>
    <parent link="right_front_axle"/>
    <child link="right_front_wheel"/>
    <origin xyz="0 0 0"/>
  </joint>
  <transmission name="right_front_axle_trans">
    <type>transmission_interface/SimpleTransmission</type>
    <actuator name="right_front_axle_motor">
      <mechanicalReduction>1</mechanicalReduction>
    </actuator>
    <joint name="base_to_right_front_axle">
      <hardwareInterface>hardware_interface/PositionJointInterface</hardwareInterface>
      <!-- <hardwareInterface>hardware_interface/PositionJointInterface</hardwareInterface> -->
    </joint>
  </transmission>
  <!-- <xacro:wheel_gazebo side="${side}" fob="${fob}"> -->
  <link name="left_front_wheel">
    <visual>
      <geometry>
        <mesh filename="/home/eichmeierbr/mrob/src/avc_urdf/meshes/wheels.DAE" scale="0.001 0.001 0.001"/>
      </geometry>
      <origin rpy="1.57 0 3.14" xyz="0 0.022 0"/>
    </visual>
    <collision>
      <geometry>
        <cylinder length="0.043" radius="0.05"/>
      </geometry>
      <origin rpy="1.57075 0 0" xyz="0 0 0"/>
    </collision>
    <inertial>
      <mass value="1"/>
      <inertia ixx="0.4" ixy="0.0" ixz="0.0" iyy="0.4" iyz="0.0" izz="0.4"/>
    </inertial>
  </link>
  <link name="left_front_axle">
    <inertial>
      <mass value="0.001"/>
      <inertia ixx="0.0" ixy="0.0" ixz="0.0" iyy="0.0" iyz="0.0" izz="0.0"/>
    </inertial>
  </link>
  <joint name="base_to_left_front_axle" type="revolute">
    <axis xyz="0 0 1"/>
    <limit effort="0.001" lower="-0.785" upper="0.785" velocity="0.5"/>
    <parent link="base_link"/>
    <child link="left_front_axle"/>
    <origin xyz="0.1535 0.1215 -0.075"/>
  </joint>
  <joint name="left_front_wheel_joint" type="continuous">
    <axis xyz="0 1 0"/>
    <parent link="left_front_axle"/>
    <child link="left_front_wheel"/>
    <origin xyz="0 0 0"/>
  </joint>
  <transmission name="left_front_axle_trans">
    <type>transmission_interface/SimpleTransmission</type>
    <actuator name="left_front_axle_motor">
      <mechanicalReduction>1</mechanicalReduction>
    </actuator>
    <joint name="base_to_left_front_axle">
      <hardwareInterface>hardware_interface/PositionJointInterface</hardwareInterface>
      <!-- <hardwareInterface>hardware_interface/PositionJointInterface</hardwareInterface> -->
    </joint>
  </transmission>
  <!-- <xacro:wheel_gazebo side="${side}" fob="${fob}"> -->
  <link name="right_back_wheel">
    <visual>
      <geometry>
        <mesh filename="/home/eichmeierbr/mrob/src/avc_urdf/meshes/wheels.DAE" scale="0.001 0.001 0.001"/>
      </geometry>
      <origin rpy="1.57 0 0" xyz="0 0.022 0"/>
    </visual>
    <collision>
      <geometry>
        <cylinder length="0.043" radius="0.05"/>
      </geometry>
      <origin rpy="1.57075 0 0" xyz="0 0 0"/>
    </collision>
    <inertial>
      <mass value="1"/>
      <inertia ixx="0.4" ixy="0.0" ixz="0.0" iyy="0.4" iyz="0.0" izz="0.4"/>
    </inertial>
  </link>
  <joint name="right_back_wheel_joint" type="continuous">
    <axis xyz="0 1 0"/>
    <parent link="base_link"/>
    <child link="right_back_wheel"/>
    <origin xyz="-0.1763 -0.1215 -0.075"/>
  </joint>
  <!-- <xacro:wheel_gazebo side="${side}" fob="${fob}"> -->
  <link name="left_back_wheel">
    <visual>
      <geometry>
        <mesh filename="/home/eichmeierbr/mrob/src/avc_urdf/meshes/wheels.DAE" scale="0.001 0.001 0.001"/>
      </geometry>
      <origin rpy="1.57 0 3.14" xyz="0 0.022 0"/>
    </visual>
    <collision>
      <geometry>
        <cylinder length="0.043" radius="0.05"/>
      </geometry>
      <origin rpy="1.57075 0 0" xyz="0 0 0"/>
    </collision>
    <inertial>
      <mass value="1"/>
      <inertia ixx="0.4" ixy="0.0" ixz="0.0" iyy="0.4" iyz="0.0" izz="0.4"/>
    </inertial>
  </link>
  <joint name="left_back_wheel_joint" type="continuous">
    <axis xyz="0 1 0"/>
    <parent link="base_link"/>
    <child link="left_back_wheel"/>
    <origin xyz="-0.1763 0.1215 -0.075"/>
  </joint>
  <!-- <xacro:wheel_gazebo side="${side}" fob="${fob}"> -->
  <!-- <xacro:imu /> -->
  <!-- <xacro:lidar /> TODO -->
  <gazebo>
    <plugin filename="libgazebo_ros_control.so" name="gazebo_ros_control">
      <robotNamespace>/</robotNamespace>
      <robotSimType>gazebo_ros_control/DefaultRobotHWSim</robotSimType>
      <legacyModeNS>true</legacyModeNS>
    </plugin>
  </gazebo>
</robot>

